2020-03-30 23:48:05,789 - waitlist.sso - ERROR - repeated_verify - 72 - SSO JSON Failure, trying workaround...
2020-03-30 23:48:58,592 - waitlist.sso - ERROR - repeated_verify - 72 - SSO JSON Failure, trying workaround...
2020-03-30 23:49:37,974 - waitlist.base - ERROR - log_exception - 1891 - Exception on /fc_sso/cb [GET]
Traceback (most recent call last):
  File "/home/kim/.local/lib/python3.6/site-packages/flask/app.py", line 2446, in wsgi_app
    response = self.full_dispatch_request()
  File "/home/kim/.local/lib/python3.6/site-packages/flask/app.py", line 1951, in full_dispatch_request
    rv = self.handle_user_exception(e)
  File "/home/kim/.local/lib/python3.6/site-packages/flask/app.py", line 1820, in handle_user_exception
    reraise(exc_type, exc_value, tb)
  File "/home/kim/.local/lib/python3.6/site-packages/flask/_compat.py", line 39, in reraise
    raise value
  File "/home/kim/.local/lib/python3.6/site-packages/flask/app.py", line 1949, in full_dispatch_request
    rv = self.dispatch_request()
  File "/home/kim/.local/lib/python3.6/site-packages/flask/app.py", line 1935, in dispatch_request
    return self.view_functions[rule.endpoint](**req.view_args)
  File "/home/kim/github/eve-inc-waitlist/waitlist/blueprints/fc_sso.py", line 59, in login_cb
    handle_key = state.split('-', 1)[0]
AttributeError: 'NoneType' object has no attribute 'split'
2020-03-30 23:57:51,145 - waitlist.base - ERROR - log_exception - 1891 - Exception on /settings/ship_assignment/col/edit [GET]
Traceback (most recent call last):
  File "/home/kim/.local/lib/python3.6/site-packages/flask/app.py", line 2446, in wsgi_app
    response = self.full_dispatch_request()
  File "/home/kim/.local/lib/python3.6/site-packages/flask/app.py", line 1951, in full_dispatch_request
    rv = self.handle_user_exception(e)
  File "/home/kim/.local/lib/python3.6/site-packages/flask/app.py", line 1820, in handle_user_exception
    reraise(exc_type, exc_value, tb)
  File "/home/kim/.local/lib/python3.6/site-packages/flask/_compat.py", line 39, in reraise
    raise value
  File "/home/kim/.local/lib/python3.6/site-packages/flask/app.py", line 1949, in full_dispatch_request
    rv = self.dispatch_request()
  File "/home/kim/.local/lib/python3.6/site-packages/flask/app.py", line 1935, in dispatch_request
    return self.view_functions[rule.endpoint](**req.view_args)
  File "/home/kim/.local/lib/python3.6/site-packages/flask_login/utils.py", line 272, in decorated_view
    return func(*args, **kwargs)
  File "/home/kim/.local/lib/python3.6/site-packages/flask_principal.py", line 199, in _decorated
    rv = f(*args, **kw)
  File "/home/kim/github/eve-inc-waitlist/waitlist/blueprints/settings/ship_assignment.py", line 38, in collection_edit
    cid: int = int(request.args.get('collection_id'))
TypeError: int() argument must be a string, a bytes-like object or a number, not 'NoneType'
2020-03-31 00:04:44,073 - waitlist.utility.swagger.eve.character - ERROR - get_fleet_info - 43 - Got error requesting fleet info for character=1277504799
2020-03-31 00:04:44,073 - waitlist.utility.outgate.character.info - ERROR - get_character_fleet_id - 133 - Failed to get fleet id. Error Code is: unexpected end of JSON input
2020-03-31 00:05:35,602 - waitlist.utility.swagger.eve.character - ERROR - get_fleet_info - 43 - Got error requesting fleet info for character=1277504799
2020-03-31 00:05:35,602 - waitlist.utility.outgate.character.info - ERROR - get_character_fleet_id - 133 - Failed to get fleet id. Error Code is: unexpected end of JSON input
2020-03-31 00:06:43,778 - waitlist.sso - ERROR - repeated_verify - 72 - SSO JSON Failure, trying workaround...
2020-03-31 00:07:13,382 - waitlist.base - ERROR - log_exception - 1891 - Exception on /xup/submit [POST]
Traceback (most recent call last):
  File "/home/kim/.local/lib/python3.6/site-packages/flask/app.py", line 2446, in wsgi_app
    response = self.full_dispatch_request()
  File "/home/kim/.local/lib/python3.6/site-packages/flask/app.py", line 1951, in full_dispatch_request
    rv = self.handle_user_exception(e)
  File "/home/kim/.local/lib/python3.6/site-packages/flask/app.py", line 1820, in handle_user_exception
    reraise(exc_type, exc_value, tb)
  File "/home/kim/.local/lib/python3.6/site-packages/flask/_compat.py", line 39, in reraise
    raise value
  File "/home/kim/.local/lib/python3.6/site-packages/flask/app.py", line 1949, in full_dispatch_request
    rv = self.dispatch_request()
  File "/home/kim/.local/lib/python3.6/site-packages/flask/app.py", line 1935, in dispatch_request
    return self.view_functions[rule.endpoint](**req.view_args)
  File "/home/kim/.local/lib/python3.6/site-packages/flask_login/utils.py", line 272, in decorated_view
    return func(*args, **kwargs)
  File "/home/kim/github/eve-inc-waitlist/waitlist/blueprints/xup/submission.py", line 202, in submit
    mod_list = parse_dna_fitting(dna_fit)
  File "/home/kim/github/eve-inc-waitlist/waitlist/utility/fitting_utils.py", line 232, in parse_dna_fitting
    raise ValueError("InvType with id=" + mod_id + " not found")
TypeError: must be str, not int
2020-03-31 00:07:19,773 - waitlist.base - ERROR - log_exception - 1891 - Exception on /xup/submit [POST]
Traceback (most recent call last):
  File "/home/kim/.local/lib/python3.6/site-packages/flask/app.py", line 2446, in wsgi_app
    response = self.full_dispatch_request()
  File "/home/kim/.local/lib/python3.6/site-packages/flask/app.py", line 1951, in full_dispatch_request
    rv = self.handle_user_exception(e)
  File "/home/kim/.local/lib/python3.6/site-packages/flask/app.py", line 1820, in handle_user_exception
    reraise(exc_type, exc_value, tb)
  File "/home/kim/.local/lib/python3.6/site-packages/flask/_compat.py", line 39, in reraise
    raise value
  File "/home/kim/.local/lib/python3.6/site-packages/flask/app.py", line 1949, in full_dispatch_request
    rv = self.dispatch_request()
  File "/home/kim/.local/lib/python3.6/site-packages/flask/app.py", line 1935, in dispatch_request
    return self.view_functions[rule.endpoint](**req.view_args)
  File "/home/kim/.local/lib/python3.6/site-packages/flask_login/utils.py", line 272, in decorated_view
    return func(*args, **kwargs)
  File "/home/kim/github/eve-inc-waitlist/waitlist/blueprints/xup/submission.py", line 202, in submit
    mod_list = parse_dna_fitting(dna_fit)
  File "/home/kim/github/eve-inc-waitlist/waitlist/utility/fitting_utils.py", line 232, in parse_dna_fitting
    raise ValueError("InvType with id=" + mod_id + " not found")
TypeError: must be str, not int
2020-03-31 00:08:13,410 - waitlist.base - ERROR - log_exception - 1891 - Exception on /xup/submit [POST]
Traceback (most recent call last):
  File "/home/kim/.local/lib/python3.6/site-packages/flask/app.py", line 2446, in wsgi_app
    response = self.full_dispatch_request()
  File "/home/kim/.local/lib/python3.6/site-packages/flask/app.py", line 1951, in full_dispatch_request
    rv = self.handle_user_exception(e)
  File "/home/kim/.local/lib/python3.6/site-packages/flask/app.py", line 1820, in handle_user_exception
    reraise(exc_type, exc_value, tb)
  File "/home/kim/.local/lib/python3.6/site-packages/flask/_compat.py", line 39, in reraise
    raise value
  File "/home/kim/.local/lib/python3.6/site-packages/flask/app.py", line 1949, in full_dispatch_request
    rv = self.dispatch_request()
  File "/home/kim/.local/lib/python3.6/site-packages/flask/app.py", line 1935, in dispatch_request
    return self.view_functions[rule.endpoint](**req.view_args)
  File "/home/kim/.local/lib/python3.6/site-packages/flask_login/utils.py", line 272, in decorated_view
    return func(*args, **kwargs)
  File "/home/kim/github/eve-inc-waitlist/waitlist/blueprints/xup/submission.py", line 202, in submit
    mod_list = parse_dna_fitting(dna_fit)
  File "/home/kim/github/eve-inc-waitlist/waitlist/utility/fitting_utils.py", line 232, in parse_dna_fitting
    raise ValueError("InvType with id=" + mod_id + " not found")
TypeError: must be str, not int
2020-03-31 00:08:42,294 - waitlist.base - ERROR - log_exception - 1891 - Exception on /xup/submit [POST]
Traceback (most recent call last):
  File "/home/kim/.local/lib/python3.6/site-packages/flask/app.py", line 2446, in wsgi_app
    response = self.full_dispatch_request()
  File "/home/kim/.local/lib/python3.6/site-packages/flask/app.py", line 1951, in full_dispatch_request
    rv = self.handle_user_exception(e)
  File "/home/kim/.local/lib/python3.6/site-packages/flask/app.py", line 1820, in handle_user_exception
    reraise(exc_type, exc_value, tb)
  File "/home/kim/.local/lib/python3.6/site-packages/flask/_compat.py", line 39, in reraise
    raise value
  File "/home/kim/.local/lib/python3.6/site-packages/flask/app.py", line 1949, in full_dispatch_request
    rv = self.dispatch_request()
  File "/home/kim/.local/lib/python3.6/site-packages/flask/app.py", line 1935, in dispatch_request
    return self.view_functions[rule.endpoint](**req.view_args)
  File "/home/kim/.local/lib/python3.6/site-packages/flask_login/utils.py", line 272, in decorated_view
    return func(*args, **kwargs)
  File "/home/kim/github/eve-inc-waitlist/waitlist/blueprints/xup/submission.py", line 202, in submit
    mod_list = parse_dna_fitting(dna_fit)
  File "/home/kim/github/eve-inc-waitlist/waitlist/utility/fitting_utils.py", line 232, in parse_dna_fitting
    raise ValueError("InvType with id=" + mod_id + " not found")
TypeError: must be str, not int
2020-03-31 00:09:28,409 - waitlist.utility.swagger.eve.character - ERROR - get_fleet_info - 43 - Got error requesting fleet info for character=1277504799
2020-03-31 00:09:28,410 - waitlist.utility.outgate.character.info - ERROR - get_character_fleet_id - 133 - Failed to get fleet id. Error Code is: unexpected end of JSON input
2020-03-31 00:09:48,573 - waitlist.utility.swagger.eve.character - ERROR - get_fleet_info - 43 - Got error requesting fleet info for character=1277504799
2020-03-31 00:09:48,573 - waitlist.utility.outgate.character.info - ERROR - get_character_fleet_id - 133 - Failed to get fleet id. Error Code is: unexpected end of JSON input
2020-03-31 00:11:03,594 - waitlist.sso - ERROR - repeated_verify - 72 - SSO JSON Failure, trying workaround...
2020-03-31 00:11:13,811 - waitlist.base - ERROR - log_exception - 1891 - Exception on /xup/submit [POST]
Traceback (most recent call last):
  File "/home/kim/.local/lib/python3.6/site-packages/flask/app.py", line 2446, in wsgi_app
    response = self.full_dispatch_request()
  File "/home/kim/.local/lib/python3.6/site-packages/flask/app.py", line 1951, in full_dispatch_request
    rv = self.handle_user_exception(e)
  File "/home/kim/.local/lib/python3.6/site-packages/flask/app.py", line 1820, in handle_user_exception
    reraise(exc_type, exc_value, tb)
  File "/home/kim/.local/lib/python3.6/site-packages/flask/_compat.py", line 39, in reraise
    raise value
  File "/home/kim/.local/lib/python3.6/site-packages/flask/app.py", line 1949, in full_dispatch_request
    rv = self.dispatch_request()
  File "/home/kim/.local/lib/python3.6/site-packages/flask/app.py", line 1935, in dispatch_request
    return self.view_functions[rule.endpoint](**req.view_args)
  File "/home/kim/.local/lib/python3.6/site-packages/flask_login/utils.py", line 272, in decorated_view
    return func(*args, **kwargs)
  File "/home/kim/github/eve-inc-waitlist/waitlist/blueprints/xup/submission.py", line 202, in submit
    mod_list = parse_dna_fitting(dna_fit)
  File "/home/kim/github/eve-inc-waitlist/waitlist/utility/fitting_utils.py", line 232, in parse_dna_fitting
    raise ValueError("InvType with id=" + mod_id + " not found")
TypeError: must be str, not int
2020-03-31 00:12:35,839 - waitlist.base - ERROR - log_exception - 1891 - Exception on /xup/submit [POST]
Traceback (most recent call last):
  File "/home/kim/.local/lib/python3.6/site-packages/flask/app.py", line 2446, in wsgi_app
    response = self.full_dispatch_request()
  File "/home/kim/.local/lib/python3.6/site-packages/flask/app.py", line 1951, in full_dispatch_request
    rv = self.handle_user_exception(e)
  File "/home/kim/.local/lib/python3.6/site-packages/flask/app.py", line 1820, in handle_user_exception
    reraise(exc_type, exc_value, tb)
  File "/home/kim/.local/lib/python3.6/site-packages/flask/_compat.py", line 39, in reraise
    raise value
  File "/home/kim/.local/lib/python3.6/site-packages/flask/app.py", line 1949, in full_dispatch_request
    rv = self.dispatch_request()
  File "/home/kim/.local/lib/python3.6/site-packages/flask/app.py", line 1935, in dispatch_request
    return self.view_functions[rule.endpoint](**req.view_args)
  File "/home/kim/.local/lib/python3.6/site-packages/flask_login/utils.py", line 272, in decorated_view
    return func(*args, **kwargs)
  File "/home/kim/github/eve-inc-waitlist/waitlist/blueprints/xup/submission.py", line 202, in submit
    mod_list = parse_dna_fitting(dna_fit)
  File "/home/kim/github/eve-inc-waitlist/waitlist/utility/fitting_utils.py", line 232, in parse_dna_fitting
    raise ValueError("InvType with id=" + mod_id + " not found")
TypeError: must be str, not int
2020-03-31 00:12:49,954 - waitlist.base - ERROR - log_exception - 1891 - Exception on /xup/submit [POST]
Traceback (most recent call last):
  File "/home/kim/.local/lib/python3.6/site-packages/flask/app.py", line 2446, in wsgi_app
    response = self.full_dispatch_request()
  File "/home/kim/.local/lib/python3.6/site-packages/flask/app.py", line 1951, in full_dispatch_request
    rv = self.handle_user_exception(e)
  File "/home/kim/.local/lib/python3.6/site-packages/flask/app.py", line 1820, in handle_user_exception
    reraise(exc_type, exc_value, tb)
  File "/home/kim/.local/lib/python3.6/site-packages/flask/_compat.py", line 39, in reraise
    raise value
  File "/home/kim/.local/lib/python3.6/site-packages/flask/app.py", line 1949, in full_dispatch_request
    rv = self.dispatch_request()
  File "/home/kim/.local/lib/python3.6/site-packages/flask/app.py", line 1935, in dispatch_request
    return self.view_functions[rule.endpoint](**req.view_args)
  File "/home/kim/.local/lib/python3.6/site-packages/flask_login/utils.py", line 272, in decorated_view
    return func(*args, **kwargs)
  File "/home/kim/github/eve-inc-waitlist/waitlist/blueprints/xup/submission.py", line 202, in submit
    mod_list = parse_dna_fitting(dna_fit)
  File "/home/kim/github/eve-inc-waitlist/waitlist/utility/fitting_utils.py", line 232, in parse_dna_fitting
    raise ValueError("InvType with id=" + mod_id + " not found")
TypeError: must be str, not int
2020-03-31 00:17:20,338 - waitlist.utility.swagger.eve.character - ERROR - get_fleet_info - 43 - Got error requesting fleet info for character=1277504799
2020-03-31 00:17:20,338 - waitlist.utility.outgate.character.info - ERROR - get_character_fleet_id - 133 - Failed to get fleet id. Error Code is: unexpected end of JSON input
2020-03-31 00:17:22,017 - waitlist.utility.swagger.eve.character - ERROR - get_fleet_info - 43 - Got error requesting fleet info for character=1277504799
2020-03-31 00:17:22,018 - waitlist.utility.outgate.character.info - ERROR - get_character_fleet_id - 133 - Failed to get fleet id. Error Code is: unexpected end of JSON input
2020-03-31 00:17:52,568 - waitlist.utility.sde - ERROR - add_constellation_info - 523 - Could not get constellation info for id=20000679 status=502
2020-03-31 00:18:01,864 - waitlist.base - ERROR - log_exception - 1891 - Exception on /xup/submit [POST]
Traceback (most recent call last):
  File "/home/kim/.local/lib/python3.6/site-packages/flask/app.py", line 2446, in wsgi_app
    response = self.full_dispatch_request()
  File "/home/kim/.local/lib/python3.6/site-packages/flask/app.py", line 1951, in full_dispatch_request
    rv = self.handle_user_exception(e)
  File "/home/kim/.local/lib/python3.6/site-packages/flask/app.py", line 1820, in handle_user_exception
    reraise(exc_type, exc_value, tb)
  File "/home/kim/.local/lib/python3.6/site-packages/flask/_compat.py", line 39, in reraise
    raise value
  File "/home/kim/.local/lib/python3.6/site-packages/flask/app.py", line 1949, in full_dispatch_request
    rv = self.dispatch_request()
  File "/home/kim/.local/lib/python3.6/site-packages/flask/app.py", line 1935, in dispatch_request
    return self.view_functions[rule.endpoint](**req.view_args)
  File "/home/kim/.local/lib/python3.6/site-packages/flask_login/utils.py", line 272, in decorated_view
    return func(*args, **kwargs)
  File "/home/kim/github/eve-inc-waitlist/waitlist/blueprints/xup/submission.py", line 202, in submit
    mod_list = parse_dna_fitting(dna_fit)
  File "/home/kim/github/eve-inc-waitlist/waitlist/utility/fitting_utils.py", line 232, in parse_dna_fitting
    raise ValueError("InvType with id=" + mod_id + " not found")
TypeError: must be str, not int
2020-03-31 00:18:05,197 - waitlist.utility.sde - ERROR - add_system_info - 565 - Could not get systen info for id=30001271 status=502
2020-03-31 00:18:07,043 - waitlist.utility.sde - ERROR - add_system_info - 565 - Could not get systen info for id=30000635 status=502
2020-03-31 00:18:11,093 - waitlist.utility.sde - ERROR - add_system_info - 565 - Could not get systen info for id=30002076 status=502
2020-03-31 00:18:12,034 - waitlist.utility.sde - ERROR - add_system_info - 565 - Could not get systen info for id=30002221 status=502
2020-03-31 00:18:21,935 - waitlist.utility.sde - ERROR - add_system_info - 565 - Could not get systen info for id=30003769 status=502
2020-03-31 00:18:27,383 - waitlist.utility.sde - ERROR - add_system_info - 565 - Could not get systen info for id=30004652 status=502
2020-03-31 00:18:39,165 - waitlist.utility.sde - ERROR - add_system_info - 565 - Could not get systen info for id=31001171 status=502
2020-03-31 00:18:49,713 - waitlist.utility.sde - ERROR - add_system_info - 565 - Could not get systen info for id=30000074 status=502
2020-03-31 00:23:58,185 - waitlist.base - ERROR - log_exception - 1891 - Exception on /xup/submit [POST]
Traceback (most recent call last):
  File "/home/kim/.local/lib/python3.6/site-packages/flask/app.py", line 2446, in wsgi_app
    response = self.full_dispatch_request()
  File "/home/kim/.local/lib/python3.6/site-packages/flask/app.py", line 1951, in full_dispatch_request
    rv = self.handle_user_exception(e)
  File "/home/kim/.local/lib/python3.6/site-packages/flask/app.py", line 1820, in handle_user_exception
    reraise(exc_type, exc_value, tb)
  File "/home/kim/.local/lib/python3.6/site-packages/flask/_compat.py", line 39, in reraise
    raise value
  File "/home/kim/.local/lib/python3.6/site-packages/flask/app.py", line 1949, in full_dispatch_request
    rv = self.dispatch_request()
  File "/home/kim/.local/lib/python3.6/site-packages/flask/app.py", line 1935, in dispatch_request
    return self.view_functions[rule.endpoint](**req.view_args)
  File "/home/kim/.local/lib/python3.6/site-packages/flask_login/utils.py", line 272, in decorated_view
    return func(*args, **kwargs)
  File "/home/kim/github/eve-inc-waitlist/waitlist/blueprints/xup/submission.py", line 259, in submit
    tag, waitlist_id = get_waitlist_type_for_fit(fit, group_id)
  File "/home/kim/github/eve-inc-waitlist/waitlist/utility/fitting_utils.py", line 407, in get_waitlist_type_for_fit
    ShipCheckCollection.waitlistGroupID == waitlist_group_id
  File "/home/kim/.local/lib/python3.6/site-packages/sqlalchemy/orm/query.py", line 3368, in one
    raise orm_exc.NoResultFound("No row was found for one()")
sqlalchemy.orm.exc.NoResultFound: No row was found for one()
2020-03-31 00:25:17,219 - waitlist.utility.swagger.eve.character - ERROR - get_fleet_info - 43 - Got error requesting fleet info for character=1277504799
2020-03-31 00:25:17,219 - waitlist.utility.outgate.character.info - ERROR - get_character_fleet_id - 133 - Failed to get fleet id. Error Code is: unexpected end of JSON input
2020-03-31 00:25:41,040 - waitlist.utility.swagger.eve.character - ERROR - get_fleet_info - 43 - Got error requesting fleet info for character=1277504799
2020-03-31 00:25:41,041 - waitlist.utility.outgate.character.info - ERROR - get_character_fleet_id - 133 - Failed to get fleet id. Error Code is: unexpected end of JSON input
2020-03-31 00:25:51,494 - waitlist.utility.swagger.eve.character - ERROR - get_fleet_info - 43 - Got error requesting fleet info for character=1277504799
2020-03-31 00:25:51,495 - waitlist.utility.outgate.character.info - ERROR - get_character_fleet_id - 133 - Failed to get fleet id. Error Code is: unexpected end of JSON input
2020-03-31 00:25:52,975 - waitlist.utility.swagger.eve.character - ERROR - get_fleet_info - 43 - Got error requesting fleet info for character=1277504799
2020-03-31 00:25:52,975 - waitlist.utility.outgate.character.info - ERROR - get_character_fleet_id - 133 - Failed to get fleet id. Error Code is: unexpected end of JSON input
2020-03-31 00:26:27,517 - waitlist.base - ERROR - log_exception - 1891 - Exception on /settings/ship_assignment/col/edit [GET]
Traceback (most recent call last):
  File "/home/kim/.local/lib/python3.6/site-packages/flask/app.py", line 2446, in wsgi_app
    response = self.full_dispatch_request()
  File "/home/kim/.local/lib/python3.6/site-packages/flask/app.py", line 1951, in full_dispatch_request
    rv = self.handle_user_exception(e)
  File "/home/kim/.local/lib/python3.6/site-packages/flask/app.py", line 1820, in handle_user_exception
    reraise(exc_type, exc_value, tb)
  File "/home/kim/.local/lib/python3.6/site-packages/flask/_compat.py", line 39, in reraise
    raise value
  File "/home/kim/.local/lib/python3.6/site-packages/flask/app.py", line 1949, in full_dispatch_request
    rv = self.dispatch_request()
  File "/home/kim/.local/lib/python3.6/site-packages/flask/app.py", line 1935, in dispatch_request
    return self.view_functions[rule.endpoint](**req.view_args)
  File "/home/kim/.local/lib/python3.6/site-packages/flask_login/utils.py", line 272, in decorated_view
    return func(*args, **kwargs)
  File "/home/kim/.local/lib/python3.6/site-packages/flask_principal.py", line 199, in _decorated
    rv = f(*args, **kw)
  File "/home/kim/github/eve-inc-waitlist/waitlist/blueprints/settings/ship_assignment.py", line 38, in collection_edit
    cid: int = int(request.args.get('collection_id'))
TypeError: int() argument must be a string, a bytes-like object or a number, not 'NoneType'
2020-03-31 00:27:05,774 - waitlist.base - ERROR - log_exception - 1891 - Exception on /settings/ship_assignment/col/add [POST]
Traceback (most recent call last):
  File "/home/kim/.local/lib/python3.6/site-packages/sqlalchemy/engine/base.py", line 1248, in _execute_context
    cursor, statement, parameters, context
  File "/home/kim/.local/lib/python3.6/site-packages/sqlalchemy/engine/default.py", line 588, in do_execute
    cursor.execute(statement, parameters)
  File "/home/kim/.local/lib/python3.6/site-packages/MySQLdb/cursors.py", line 209, in execute
    res = self._query(query)
  File "/home/kim/.local/lib/python3.6/site-packages/MySQLdb/cursors.py", line 315, in _query
    db.query(q)
  File "/home/kim/.local/lib/python3.6/site-packages/MySQLdb/connections.py", line 239, in query
    _mysql.connection.query(self, query)
MySQLdb._exceptions.IntegrityError: (1062, "Duplicate entry '1' for key 'uq_ship_check_collection_waitlist_group_id'")

The above exception was the direct cause of the following exception:

Traceback (most recent call last):
  File "/home/kim/.local/lib/python3.6/site-packages/flask/app.py", line 2446, in wsgi_app
    response = self.full_dispatch_request()
  File "/home/kim/.local/lib/python3.6/site-packages/flask/app.py", line 1951, in full_dispatch_request
    rv = self.handle_user_exception(e)
  File "/home/kim/.local/lib/python3.6/site-packages/flask/app.py", line 1820, in handle_user_exception
    reraise(exc_type, exc_value, tb)
  File "/home/kim/.local/lib/python3.6/site-packages/flask/_compat.py", line 39, in reraise
    raise value
  File "/home/kim/.local/lib/python3.6/site-packages/flask/app.py", line 1949, in full_dispatch_request
    rv = self.dispatch_request()
  File "/home/kim/.local/lib/python3.6/site-packages/flask/app.py", line 1935, in dispatch_request
    return self.view_functions[rule.endpoint](**req.view_args)
  File "/home/kim/.local/lib/python3.6/site-packages/flask_login/utils.py", line 272, in decorated_view
    return func(*args, **kwargs)
  File "/home/kim/.local/lib/python3.6/site-packages/flask_principal.py", line 199, in _decorated
    rv = f(*args, **kw)
  File "/home/kim/github/eve-inc-waitlist/waitlist/blueprints/settings/ship_assignment.py", line 82, in collection_add
    db.session.commit()
  File "/home/kim/.local/lib/python3.6/site-packages/sqlalchemy/orm/scoping.py", line 162, in do
    return getattr(self.registry(), name)(*args, **kwargs)
  File "/home/kim/.local/lib/python3.6/site-packages/sqlalchemy/orm/session.py", line 1036, in commit
    self.transaction.commit()
  File "/home/kim/.local/lib/python3.6/site-packages/sqlalchemy/orm/session.py", line 503, in commit
    self._prepare_impl()
  File "/home/kim/.local/lib/python3.6/site-packages/sqlalchemy/orm/session.py", line 482, in _prepare_impl
    self.session.flush()
  File "/home/kim/.local/lib/python3.6/site-packages/sqlalchemy/orm/session.py", line 2496, in flush
    self._flush(objects)
  File "/home/kim/.local/lib/python3.6/site-packages/sqlalchemy/orm/session.py", line 2637, in _flush
    transaction.rollback(_capture_exception=True)
  File "/home/kim/.local/lib/python3.6/site-packages/sqlalchemy/util/langhelpers.py", line 69, in __exit__
    exc_value, with_traceback=exc_tb,
  File "/home/kim/.local/lib/python3.6/site-packages/sqlalchemy/util/compat.py", line 178, in raise_
    raise exception
  File "/home/kim/.local/lib/python3.6/site-packages/sqlalchemy/orm/session.py", line 2597, in _flush
    flush_context.execute()
  File "/home/kim/.local/lib/python3.6/site-packages/sqlalchemy/orm/unitofwork.py", line 422, in execute
    rec.execute(self)
  File "/home/kim/.local/lib/python3.6/site-packages/sqlalchemy/orm/unitofwork.py", line 589, in execute
    uow,
  File "/home/kim/.local/lib/python3.6/site-packages/sqlalchemy/orm/persistence.py", line 245, in save_obj
    insert,
  File "/home/kim/.local/lib/python3.6/site-packages/sqlalchemy/orm/persistence.py", line 1136, in _emit_insert_statements
    statement, params
  File "/home/kim/.local/lib/python3.6/site-packages/sqlalchemy/engine/base.py", line 984, in execute
    return meth(self, multiparams, params)
  File "/home/kim/.local/lib/python3.6/site-packages/sqlalchemy/sql/elements.py", line 293, in _execute_on_connection
    return connection._execute_clauseelement(self, multiparams, params)
  File "/home/kim/.local/lib/python3.6/site-packages/sqlalchemy/engine/base.py", line 1103, in _execute_clauseelement
    distilled_params,
  File "/home/kim/.local/lib/python3.6/site-packages/sqlalchemy/engine/base.py", line 1288, in _execute_context
    e, statement, parameters, cursor, context
  File "/home/kim/.local/lib/python3.6/site-packages/sqlalchemy/engine/base.py", line 1482, in _handle_dbapi_exception
    sqlalchemy_exception, with_traceback=exc_info[2], from_=e
  File "/home/kim/.local/lib/python3.6/site-packages/sqlalchemy/util/compat.py", line 178, in raise_
    raise exception
  File "/home/kim/.local/lib/python3.6/site-packages/sqlalchemy/engine/base.py", line 1248, in _execute_context
    cursor, statement, parameters, context
  File "/home/kim/.local/lib/python3.6/site-packages/sqlalchemy/engine/default.py", line 588, in do_execute
    cursor.execute(statement, parameters)
  File "/home/kim/.local/lib/python3.6/site-packages/MySQLdb/cursors.py", line 209, in execute
    res = self._query(query)
  File "/home/kim/.local/lib/python3.6/site-packages/MySQLdb/cursors.py", line 315, in _query
    db.query(q)
  File "/home/kim/.local/lib/python3.6/site-packages/MySQLdb/connections.py", line 239, in query
    _mysql.connection.query(self, query)
sqlalchemy.exc.IntegrityError: (MySQLdb._exceptions.IntegrityError) (1062, "Duplicate entry '1' for key 'uq_ship_check_collection_waitlist_group_id'")
[SQL: INSERT INTO ship_check_collection (collection_name, waitlist_group_id, default_target_id, default_tag) VALUES (%s, %s, %s, %s)]
[parameters: ('Sniper', 1, 4, 'Sniper')]
(Background on this error at: http://sqlalche.me/e/gkpj)
2020-03-31 00:27:24,981 - waitlist.base - ERROR - log_exception - 1891 - Exception on /settings/ship_assignment/col/add [POST]
Traceback (most recent call last):
  File "/home/kim/.local/lib/python3.6/site-packages/sqlalchemy/engine/base.py", line 1248, in _execute_context
    cursor, statement, parameters, context
  File "/home/kim/.local/lib/python3.6/site-packages/sqlalchemy/engine/default.py", line 588, in do_execute
    cursor.execute(statement, parameters)
  File "/home/kim/.local/lib/python3.6/site-packages/MySQLdb/cursors.py", line 209, in execute
    res = self._query(query)
  File "/home/kim/.local/lib/python3.6/site-packages/MySQLdb/cursors.py", line 315, in _query
    db.query(q)
  File "/home/kim/.local/lib/python3.6/site-packages/MySQLdb/connections.py", line 239, in query
    _mysql.connection.query(self, query)
MySQLdb._exceptions.IntegrityError: (1062, "Duplicate entry '1' for key 'uq_ship_check_collection_waitlist_group_id'")

The above exception was the direct cause of the following exception:

Traceback (most recent call last):
  File "/home/kim/.local/lib/python3.6/site-packages/flask/app.py", line 2446, in wsgi_app
    response = self.full_dispatch_request()
  File "/home/kim/.local/lib/python3.6/site-packages/flask/app.py", line 1951, in full_dispatch_request
    rv = self.handle_user_exception(e)
  File "/home/kim/.local/lib/python3.6/site-packages/flask/app.py", line 1820, in handle_user_exception
    reraise(exc_type, exc_value, tb)
  File "/home/kim/.local/lib/python3.6/site-packages/flask/_compat.py", line 39, in reraise
    raise value
  File "/home/kim/.local/lib/python3.6/site-packages/flask/app.py", line 1949, in full_dispatch_request
    rv = self.dispatch_request()
  File "/home/kim/.local/lib/python3.6/site-packages/flask/app.py", line 1935, in dispatch_request
    return self.view_functions[rule.endpoint](**req.view_args)
  File "/home/kim/.local/lib/python3.6/site-packages/flask_login/utils.py", line 272, in decorated_view
    return func(*args, **kwargs)
  File "/home/kim/.local/lib/python3.6/site-packages/flask_principal.py", line 199, in _decorated
    rv = f(*args, **kw)
  File "/home/kim/github/eve-inc-waitlist/waitlist/blueprints/settings/ship_assignment.py", line 82, in collection_add
    db.session.commit()
  File "/home/kim/.local/lib/python3.6/site-packages/sqlalchemy/orm/scoping.py", line 162, in do
    return getattr(self.registry(), name)(*args, **kwargs)
  File "/home/kim/.local/lib/python3.6/site-packages/sqlalchemy/orm/session.py", line 1036, in commit
    self.transaction.commit()
  File "/home/kim/.local/lib/python3.6/site-packages/sqlalchemy/orm/session.py", line 503, in commit
    self._prepare_impl()
  File "/home/kim/.local/lib/python3.6/site-packages/sqlalchemy/orm/session.py", line 482, in _prepare_impl
    self.session.flush()
  File "/home/kim/.local/lib/python3.6/site-packages/sqlalchemy/orm/session.py", line 2496, in flush
    self._flush(objects)
  File "/home/kim/.local/lib/python3.6/site-packages/sqlalchemy/orm/session.py", line 2637, in _flush
    transaction.rollback(_capture_exception=True)
  File "/home/kim/.local/lib/python3.6/site-packages/sqlalchemy/util/langhelpers.py", line 69, in __exit__
    exc_value, with_traceback=exc_tb,
  File "/home/kim/.local/lib/python3.6/site-packages/sqlalchemy/util/compat.py", line 178, in raise_
    raise exception
  File "/home/kim/.local/lib/python3.6/site-packages/sqlalchemy/orm/session.py", line 2597, in _flush
    flush_context.execute()
  File "/home/kim/.local/lib/python3.6/site-packages/sqlalchemy/orm/unitofwork.py", line 422, in execute
    rec.execute(self)
  File "/home/kim/.local/lib/python3.6/site-packages/sqlalchemy/orm/unitofwork.py", line 589, in execute
    uow,
  File "/home/kim/.local/lib/python3.6/site-packages/sqlalchemy/orm/persistence.py", line 245, in save_obj
    insert,
  File "/home/kim/.local/lib/python3.6/site-packages/sqlalchemy/orm/persistence.py", line 1136, in _emit_insert_statements
    statement, params
  File "/home/kim/.local/lib/python3.6/site-packages/sqlalchemy/engine/base.py", line 984, in execute
    return meth(self, multiparams, params)
  File "/home/kim/.local/lib/python3.6/site-packages/sqlalchemy/sql/elements.py", line 293, in _execute_on_connection
    return connection._execute_clauseelement(self, multiparams, params)
  File "/home/kim/.local/lib/python3.6/site-packages/sqlalchemy/engine/base.py", line 1103, in _execute_clauseelement
    distilled_params,
  File "/home/kim/.local/lib/python3.6/site-packages/sqlalchemy/engine/base.py", line 1288, in _execute_context
    e, statement, parameters, cursor, context
  File "/home/kim/.local/lib/python3.6/site-packages/sqlalchemy/engine/base.py", line 1482, in _handle_dbapi_exception
    sqlalchemy_exception, with_traceback=exc_info[2], from_=e
  File "/home/kim/.local/lib/python3.6/site-packages/sqlalchemy/util/compat.py", line 178, in raise_
    raise exception
  File "/home/kim/.local/lib/python3.6/site-packages/sqlalchemy/engine/base.py", line 1248, in _execute_context
    cursor, statement, parameters, context
  File "/home/kim/.local/lib/python3.6/site-packages/sqlalchemy/engine/default.py", line 588, in do_execute
    cursor.execute(statement, parameters)
  File "/home/kim/.local/lib/python3.6/site-packages/MySQLdb/cursors.py", line 209, in execute
    res = self._query(query)
  File "/home/kim/.local/lib/python3.6/site-packages/MySQLdb/cursors.py", line 315, in _query
    db.query(q)
  File "/home/kim/.local/lib/python3.6/site-packages/MySQLdb/connections.py", line 239, in query
    _mysql.connection.query(self, query)
sqlalchemy.exc.IntegrityError: (MySQLdb._exceptions.IntegrityError) (1062, "Duplicate entry '1' for key 'uq_ship_check_collection_waitlist_group_id'")
[SQL: INSERT INTO ship_check_collection (collection_name, waitlist_group_id, default_target_id, default_tag) VALUES (%s, %s, %s, %s)]
[parameters: ('Paladin', 1, 4, 'Paladin')]
(Background on this error at: http://sqlalche.me/e/gkpj)
2020-03-31 00:27:48,537 - waitlist.base - ERROR - log_exception - 1891 - Exception on /xup/submit [POST]
Traceback (most recent call last):
  File "/home/kim/.local/lib/python3.6/site-packages/flask/app.py", line 2446, in wsgi_app
    response = self.full_dispatch_request()
  File "/home/kim/.local/lib/python3.6/site-packages/flask/app.py", line 1951, in full_dispatch_request
    rv = self.handle_user_exception(e)
  File "/home/kim/.local/lib/python3.6/site-packages/flask/app.py", line 1820, in handle_user_exception
    reraise(exc_type, exc_value, tb)
  File "/home/kim/.local/lib/python3.6/site-packages/flask/_compat.py", line 39, in reraise
    raise value
  File "/home/kim/.local/lib/python3.6/site-packages/flask/app.py", line 1949, in full_dispatch_request
    rv = self.dispatch_request()
  File "/home/kim/.local/lib/python3.6/site-packages/flask/app.py", line 1935, in dispatch_request
    return self.view_functions[rule.endpoint](**req.view_args)
  File "/home/kim/.local/lib/python3.6/site-packages/flask_login/utils.py", line 272, in decorated_view
    return func(*args, **kwargs)
  File "/home/kim/github/eve-inc-waitlist/waitlist/blueprints/xup/submission.py", line 259, in submit
    tag, waitlist_id = get_waitlist_type_for_fit(fit, group_id)
  File "/home/kim/github/eve-inc-waitlist/waitlist/utility/fitting_utils.py", line 448, in get_waitlist_type_for_fit
    module_data: Optional[Tuple[int, Tuple[Decimal, AbstractSet[str]]]] = get_waitlist_type_for_modules(check_tuple[0], fit)
  File "/home/kim/github/eve-inc-waitlist/waitlist/utility/fitting_utils.py", line 364, in get_waitlist_type_for_modules
    for check in checks:
TypeError: 'NoneType' object is not iterable
2020-03-31 00:28:27,005 - waitlist.base - ERROR - log_exception - 1891 - Exception on /settings/ship_assignment/col/add [POST]
Traceback (most recent call last):
  File "/home/kim/.local/lib/python3.6/site-packages/sqlalchemy/engine/base.py", line 1248, in _execute_context
    cursor, statement, parameters, context
  File "/home/kim/.local/lib/python3.6/site-packages/sqlalchemy/engine/default.py", line 588, in do_execute
    cursor.execute(statement, parameters)
  File "/home/kim/.local/lib/python3.6/site-packages/MySQLdb/cursors.py", line 209, in execute
    res = self._query(query)
  File "/home/kim/.local/lib/python3.6/site-packages/MySQLdb/cursors.py", line 315, in _query
    db.query(q)
  File "/home/kim/.local/lib/python3.6/site-packages/MySQLdb/connections.py", line 239, in query
    _mysql.connection.query(self, query)
MySQLdb._exceptions.IntegrityError: (1062, "Duplicate entry '1' for key 'uq_ship_check_collection_waitlist_group_id'")

The above exception was the direct cause of the following exception:

Traceback (most recent call last):
  File "/home/kim/.local/lib/python3.6/site-packages/flask/app.py", line 2446, in wsgi_app
    response = self.full_dispatch_request()
  File "/home/kim/.local/lib/python3.6/site-packages/flask/app.py", line 1951, in full_dispatch_request
    rv = self.handle_user_exception(e)
  File "/home/kim/.local/lib/python3.6/site-packages/flask/app.py", line 1820, in handle_user_exception
    reraise(exc_type, exc_value, tb)
  File "/home/kim/.local/lib/python3.6/site-packages/flask/_compat.py", line 39, in reraise
    raise value
  File "/home/kim/.local/lib/python3.6/site-packages/flask/app.py", line 1949, in full_dispatch_request
    rv = self.dispatch_request()
  File "/home/kim/.local/lib/python3.6/site-packages/flask/app.py", line 1935, in dispatch_request
    return self.view_functions[rule.endpoint](**req.view_args)
  File "/home/kim/.local/lib/python3.6/site-packages/flask_login/utils.py", line 272, in decorated_view
    return func(*args, **kwargs)
  File "/home/kim/.local/lib/python3.6/site-packages/flask_principal.py", line 199, in _decorated
    rv = f(*args, **kw)
  File "/home/kim/github/eve-inc-waitlist/waitlist/blueprints/settings/ship_assignment.py", line 82, in collection_add
    db.session.commit()
  File "/home/kim/.local/lib/python3.6/site-packages/sqlalchemy/orm/scoping.py", line 162, in do
    return getattr(self.registry(), name)(*args, **kwargs)
  File "/home/kim/.local/lib/python3.6/site-packages/sqlalchemy/orm/session.py", line 1036, in commit
    self.transaction.commit()
  File "/home/kim/.local/lib/python3.6/site-packages/sqlalchemy/orm/session.py", line 503, in commit
    self._prepare_impl()
  File "/home/kim/.local/lib/python3.6/site-packages/sqlalchemy/orm/session.py", line 482, in _prepare_impl
    self.session.flush()
  File "/home/kim/.local/lib/python3.6/site-packages/sqlalchemy/orm/session.py", line 2496, in flush
    self._flush(objects)
  File "/home/kim/.local/lib/python3.6/site-packages/sqlalchemy/orm/session.py", line 2637, in _flush
    transaction.rollback(_capture_exception=True)
  File "/home/kim/.local/lib/python3.6/site-packages/sqlalchemy/util/langhelpers.py", line 69, in __exit__
    exc_value, with_traceback=exc_tb,
  File "/home/kim/.local/lib/python3.6/site-packages/sqlalchemy/util/compat.py", line 178, in raise_
    raise exception
  File "/home/kim/.local/lib/python3.6/site-packages/sqlalchemy/orm/session.py", line 2597, in _flush
    flush_context.execute()
  File "/home/kim/.local/lib/python3.6/site-packages/sqlalchemy/orm/unitofwork.py", line 422, in execute
    rec.execute(self)
  File "/home/kim/.local/lib/python3.6/site-packages/sqlalchemy/orm/unitofwork.py", line 589, in execute
    uow,
  File "/home/kim/.local/lib/python3.6/site-packages/sqlalchemy/orm/persistence.py", line 245, in save_obj
    insert,
  File "/home/kim/.local/lib/python3.6/site-packages/sqlalchemy/orm/persistence.py", line 1136, in _emit_insert_statements
    statement, params
  File "/home/kim/.local/lib/python3.6/site-packages/sqlalchemy/engine/base.py", line 984, in execute
    return meth(self, multiparams, params)
  File "/home/kim/.local/lib/python3.6/site-packages/sqlalchemy/sql/elements.py", line 293, in _execute_on_connection
    return connection._execute_clauseelement(self, multiparams, params)
  File "/home/kim/.local/lib/python3.6/site-packages/sqlalchemy/engine/base.py", line 1103, in _execute_clauseelement
    distilled_params,
  File "/home/kim/.local/lib/python3.6/site-packages/sqlalchemy/engine/base.py", line 1288, in _execute_context
    e, statement, parameters, cursor, context
  File "/home/kim/.local/lib/python3.6/site-packages/sqlalchemy/engine/base.py", line 1482, in _handle_dbapi_exception
    sqlalchemy_exception, with_traceback=exc_info[2], from_=e
  File "/home/kim/.local/lib/python3.6/site-packages/sqlalchemy/util/compat.py", line 178, in raise_
    raise exception
  File "/home/kim/.local/lib/python3.6/site-packages/sqlalchemy/engine/base.py", line 1248, in _execute_context
    cursor, statement, parameters, context
  File "/home/kim/.local/lib/python3.6/site-packages/sqlalchemy/engine/default.py", line 588, in do_execute
    cursor.execute(statement, parameters)
  File "/home/kim/.local/lib/python3.6/site-packages/MySQLdb/cursors.py", line 209, in execute
    res = self._query(query)
  File "/home/kim/.local/lib/python3.6/site-packages/MySQLdb/cursors.py", line 315, in _query
    db.query(q)
  File "/home/kim/.local/lib/python3.6/site-packages/MySQLdb/connections.py", line 239, in query
    _mysql.connection.query(self, query)
sqlalchemy.exc.IntegrityError: (MySQLdb._exceptions.IntegrityError) (1062, "Duplicate entry '1' for key 'uq_ship_check_collection_waitlist_group_id'")
[SQL: INSERT INTO ship_check_collection (collection_name, waitlist_group_id, default_target_id, default_tag) VALUES (%s, %s, %s, %s)]
[parameters: ('Oni', 1, 2, 'Oni')]
(Background on this error at: http://sqlalche.me/e/gkpj)
